root@abhishek-VirtualBox:/var/log/apache2# tail -20f error.log
[Fri Nov 14 06:12:08.023144 2014] [:error] [pid 12710:tid 3043838784] [remote 10.0.2.15:52662]     return self.format('D, j M Y H:i:s O')
[Fri Nov 14 06:12:08.023159 2014] [:error] [pid 12710:tid 3043838784] [remote 10.0.2.15:52662]   File "/usr/local/lib/python2.7/dist-packages/django/utils/dateformat.py", line 35, in format
[Fri Nov 14 06:12:08.023181 2014] [:error] [pid 12710:tid 3043838784] [remote 10.0.2.15:52662]     pieces.append(force_text(getattr(self, piece)()))
[Fri Nov 14 06:12:08.023197 2014] [:error] [pid 12710:tid 3043838784] [remote 10.0.2.15:52662]   File "/usr/local/lib/python2.7/dist-packages/django/utils/encoding.py", line 100, in force_text
[Fri Nov 14 06:12:08.023354 2014] [:error] [pid 12710:tid 3043838784] [remote 10.0.2.15:52662]     s = s.__unicode__()
[Fri Nov 14 06:12:08.023375 2014] [:error] [pid 12710:tid 3043838784] [remote 10.0.2.15:52662]   File "/usr/local/lib/python2.7/dist-packages/django/utils/functional.py", line 138, in __text_cast
[Fri Nov 14 06:12:08.023559 2014] [:error] [pid 12710:tid 3043838784] [remote 10.0.2.15:52662]     return func(*self.__args, **self.__kw)
[Fri Nov 14 06:12:08.023580 2014] [:error] [pid 12710:tid 3043838784] [remote 10.0.2.15:52662]   File "/usr/local/lib/python2.7/dist-packages/django/utils/translation/__init__.py", line 76, in ugettext
[Fri Nov 14 06:12:08.023699 2014] [:error] [pid 12710:tid 3043838784] [remote 10.0.2.15:52662]     return _trans.ugettext(message)
[Fri Nov 14 06:12:08.023719 2014] [:error] [pid 12710:tid 3043838784] [remote 10.0.2.15:52662]   File "/usr/local/lib/python2.7/dist-packages/django/utils/translation/trans_real.py", line 281, in ugettext
[Fri Nov 14 06:12:08.029585 2014] [:error] [pid 12710:tid 3043838784] [remote 10.0.2.15:52662]     return do_translate(message, 'ugettext')
[Fri Nov 14 06:12:08.029680 2014] [:error] [pid 12710:tid 3043838784] [remote 10.0.2.15:52662]   File "/usr/local/lib/python2.7/dist-packages/django/utils/translation/trans_real.py", line 263, in do_translate
[Fri Nov 14 06:12:08.029764 2014] [:error] [pid 12710:tid 3043838784] [remote 10.0.2.15:52662]     _default = translation(settings.LANGUAGE_CODE)
[Fri Nov 14 06:12:08.029802 2014] [:error] [pid 12710:tid 3043838784] [remote 10.0.2.15:52662]   File "/usr/local/lib/python2.7/dist-packages/django/utils/translation/trans_real.py", line 177, in translation
[Fri Nov 14 06:12:08.029848 2014] [:error] [pid 12710:tid 3043838784] [remote 10.0.2.15:52662]     default_translation = _fetch(settings.LANGUAGE_CODE)
[Fri Nov 14 06:12:08.029883 2014] [:error] [pid 12710:tid 3043838784] [remote 10.0.2.15:52662]   File "/usr/local/lib/python2.7/dist-packages/django/utils/translation/trans_real.py", line 159, in _fetch
[Fri Nov 14 06:12:08.029925 2014] [:error] [pid 12710:tid 3043838784] [remote 10.0.2.15:52662]     app = import_module(appname)
[Fri Nov 14 06:12:08.029958 2014] [:error] [pid 12710:tid 3043838784] [remote 10.0.2.15:52662]   File "/usr/local/lib/python2.7/dist-packages/django/utils/importlib.py", line 40, in import_module
[Fri Nov 14 06:12:08.030190 2014] [:error] [pid 12710:tid 3043838784] [remote 10.0.2.15:52662]     __import__(name)
[Fri Nov 14 06:12:08.030250 2014] [:error] [pid 12710:tid 3043838784] [remote 10.0.2.15:52662] ImportError: No module named django_pph
